Workbook
Name TextRefCopy39: '[1]GIT 102Q1'!$F$39

Sheet 原始檔
A1: 物料群組 | B1: 物料類別 | C1: 說明 | D1: 銷售數量 | E1: 銷退數量 | F1: 數量合計 | G1: 銷貨收入 | H1: 銷貨折讓 | I1: 銷貨退回 | J1: 銷貨淨額 | K1: 平均單價 | L1: 銷貨成本(標準) | M1: 標準單價成本 | N1: 銷貨成本(實際) | O1: 實際單位成本
D2: 0 | E2: 0 | F2: 0 | G2: 4319802 | H2: 0 | I2: 252432 | J2: 4572234 | K2: 0 | L2: 0 | M2: 0 | N2: 0 | O2: 0
A3: A00 | B3: =VLOOKUP(A3,分群碼名稱!A:B,2) -> 燈座 | C3: 燈殼 | D3: 128158 | E3: -3 | F3: 128155 | G3: 9525252 | H3: -69 | I3: -47 | J3: 9525136 | K3: 74.33 | L3: 12905360 | M3: 100.7 | N3: 12905837 | O3: 100.7
A4: A03 | B4: =VLOOKUP(A4,分群碼名稱!A:B,2) -> 百貨 | C4: 單出反射鏡 | D4: 10304 | E4: 0 | F4: 10304 | G4: 506418 | H4: 0 | I4: 0 | J4: 506418 | K4: 49.15 | L4: 807887 | M4: 78.41 | N4: 807888 | O4: 78.41
A5: A04 | B5: =VLOOKUP(A5,分群碼名稱!A:B,2) -> 百貨 | C5: 單出遮光罩(板) | D5: 780 | E5: 0 | F5: 780 | G5: 179950 | H5: 0 | I5: 0 | J5: 179950 | K5: 230.71 | L5: 172179 | M5: 220.74 | N5: 172180 | O5: 220.74
A6: A06 | B6: =VLOOKUP(A6,分群碼名稱!A:B,2) -> 百貨 | C6: 單出飾框 | D6: 6464 | E6: 0 | F6: 6464 | G6: 650564 | H6: 0 | I6: 0 | J6: 650564 | K6: 100.64 | L6: 1528457 | M6: 236.46 | N6: 1528458 | O6: 236.46
A7: A08 | B7: =VLOOKUP(A7,分群碼名稱!A:B,2) -> 百貨 | C7: 單出底座 | D7: 10903 | E7: 0 | F7: 10903 | G7: 615517 | H7: 0 | I7: 0 | J7: 615517 | K7: 56.45 | L7: 645628 | M7: 59.22 | N7: 645627 | O7: 59.22
A8: A09 | B8: =VLOOKUP(A8,分群碼名稱!A:B,2) -> 百貨 | C8: 單出固定鐵 | D8: 0 | E8: 0 | F8: 0 | G8: 0 | H8: 0 | I8: 0 | J8: 0 | K8: 0 | L8: 0 | M8: 0 | N8: 0 | O8: 0
A9: A10 | B9: =VLOOKUP(A9,分群碼名稱!A:B,2) -> 百貨 | C9: 單出線組 | D9: 0 | E9: 0 | F9: 0 | G9: 0 | H9: 0 | I9: 0 | J9: 0 | K9: 0 | L9: 0 | M9: 0 | N9: 0 | O9: 0
A10: A11 | B10: =VLOOKUP(A10,分群碼名稱!A:B,2) -> 大燈 | C10: 大燈/頭燈 | D10: 1271548 | E10: -1645 | F10: 1269903 | G10: 2110041687 | H10: -975990 | I10: -8577212 | J10: 2100488485 | K10: 1654.05 | L10: 1405633740 | M10: 1106.88 | N10: 1407889885 | O10: 1108.66
A11: A12 | B11: =VLOOKUP(A11,分群碼名稱!A:B,2) -> 燈座 | C11: 大燈外框 | D11: 6215 | E11: 0 | F11: 6215 | G11: 1365528 | H11: 0 | I11: 0 | J11: 1365528 | K11: 219.71 | L11: 598988 | M11: 96.38 | N11: 598984 | O11: 96.38
A12: A13 | B12: =VLOOKUP(A12,分群碼名稱!A:B,2) -> 倒車燈 | C12: 倒車燈/內尾燈 | D12: 76028 | E12: -41 | F12: 75987 | G12: 50539772 | H12: -815 | I12: -45628 | J12: 50493329 | K12: 664.5 | L12: 31128334 | M12: 409.65 | N12: 31179594 | O12: 410.33
A13: A14 | B13: =VLOOKUP(A13,分群碼名稱!A:B,2) -> 邊燈 | C13: 邊燈/側邊燈 | D13: 241730 | E13: -21 | F13: 241709 | G13: 27159979 | H13: -294 | I13: -3717 | J13: 27155968 | K13: 112.35 | L13: 11815179 | M13: 48.88 | N13: 11818538 | O13: 48.9
A14: A15 | B14: =VLOOKUP(A14,分群碼名稱!A:B,2) -> 角燈 | C14: 角燈 | D14: 398314 | E14: -27 | F14: 398287 | G14: 63768340 | H14: -837 | I14: -6883 | J14: 63760620 | K14: 160.09 | L14: 38566847 | M14: 96.83 | N14: 38576159 | O14: 96.86
... A44: ASP | B44: =VLOOKUP(A44,分群碼名稱!A:B,2) -> 百貨 | C44: 單出零件包 | D44: 400 | E44: 0 | F44: 400 | G44: 409825 | H44: 0 | I44: 0 | J44: 409825 | K44: 1024.56 | L44: 226431 | M44: 566.08 | N44: 226431 | O44: 566.08
A45: D01 | B45: 原物料 | C45: 燈殼 | D45: 4878 | E45: 0 | F45: 4878 | G45: 447865 | H45: 0 | I45: 0 | J45: 447865 | K45: 91.81 | L45: 526097 | M45: 107.85 | N45: 831109 | O45: 170.38
A46: D02 | B46: 原物料 | C46: 橡膠類 | D46: 1780 | E46: 0 | F46: 1780 | G46: 9124 | H46: 0 | I46: 0 | J46: 9124 | K46: 5.13 | L46: -1331 | M46: -0.75 | N46: 7142 | O46: 4.01
A47: D03 | B47: 原物料 | C47: 反射鏡,反射片 | D47: 6429 | E47: 0 | F47: 6429 | G47: 288417 | H47: 0 | I47: 0 | J47: 288417 | K47: 44.86 | L47: -33553 | M47: -5.22 | N47: 246353 | O47: 38.32
A48: D04 | B48: 原物料 | C48: 隔光片,隔熱片,隔光罩 | D48: 2030 | E48: 0 | F48: 2030 | G48: 32191 | H48: 0 | I48: 0 | J48: 32191 | K48: 15.86 | L48: 24197 | M48: 11.92 | N48: 25613 | O48: 12.62
A49: D05 | B49: 原物料 | C49: 插座,插頭 | D49: 540 | E49: 0 | F49: 540 | G49: 18528 | H49: 0 | I49: 0 | J49: 18528 | K49: 34.31 | L49: 14518 | M49: 26.89 | N49: 14292 | O49: 26.47
A50: D06 | B50: 原物料 | C50: 外框 | D50: 4641 | E50: 0 | F50: 4641 | G50: 207886 | H50: 0 | I50: 0 | J50: 207886 | K50: 44.79 | L50: -841188 | M50: -181.25 | N50: 209388 | O50: 45.12
A51: D07 | B51: 原物料 | C51: 鐵架,固定鐵 | D51: 0 | E51: 0 | F51: 0 | G51: 0 | H51: 0 | I51: 0 | J51: 0 | K51: 0 | L51: -464 | M51: 0 | N51: 0 | O51: 0
A52: D08 | B52: 原物料 | C52: 底座,底座後蓋 | D52: 13700 | E52: 0 | F52: 13700 | G52: 958134 | H52: 0 | I52: 0 | J52: 958134 | K52: 69.94 | L52: 881563 | M52: 64.35 | N52: 838941 | O52: 61.24
A53: D09 | B53: 原物料 | C53: 固定類(含油杯,鐵板,風葉盤,小鐵類) | D53: 6904 | E53: 0 | F53: 6904 | G53: 78919 | H53: 0 | I53: 0 | J53: 78919 | K53: 11.43 | L53: 60123 | M53: 8.71 | N53: 60313 | O53: 8.74
A54: D10 | B54: 原物料 | C54: 線組 | D54: 2 | E54: 0 | F54: 2 | G54: 100 | H54: 0 | I54: 0 | J54: 100 | K54: 50 | L54: -26354 | M54: -13177 | N54: 50 | O54: 25
A55: D11 | B55: 原物料 | C55: SOCKET類,燈泡座 | D55: 6940 | E55: 0 | F55: 6940 | G55: 74226 | H55: 0 | I55: 0 | J55: 74226 | K55: 10.7 | L55: 58633 | M55: 8.45 | N55: 57695 | O55: 8.31
A56: D12 | B56: 原物料 | C56: 護板 | D56: 0 | E56: 0 | F56: 0 | G56: 0 | H56: 0 | I56: 0 | J56: 0 | K56: 0 | L56: -14 | M56: 0 | N56: 0 | O56: 0
... A103: DTM | B103: 原物料 | C103: 特殊螺絲 | D103: 1100 | E103: 0 | F103: 1100 | G103: 7420 | H103: 0 | I103: 0 | J103: 7420 | K103: 6.75 | L103: 6022 | M103: 5.47 | N103: 5974 | O103: 5.43
A104: H02 | B104: =VLOOKUP(A104,分群碼名稱!A:B,2) -> 百貨 | C104: 橡膠類 | D104: 3200 | E104: 0 | F104: 3200 | G104: 33869 | H104: 0 | I104: 0 | J104: 33869 | K104: 10.58 | L104: 25380 | M104: 7.93 | N104: 26261 | O104: 8.21
A105: H05 | B105: =VLOOKUP(A105,分群碼名稱!A:B,2) -> 百貨 | C105: 插座.插頭 | D105: 2700 | E105: 0 | F105: 2700 | G105: 7335 | H105: 0 | I105: 0 | J105: 7335 | K105: 2.72 | L105: 6214 | M105: 2.3 | N105: 6219 | O105: 2.3
A106: H09 | B106: =VLOOKUP(A106,分群碼名稱!A:B,2) -> 百貨 | C106: 固定鐵類 | D106: 19900 | E106: 0 | F106: 19900 | G106: 79650 | H106: 0 | I106: 0 | J106: 79650 | K106: 4 | L106: 61627 | M106: 3.1 | N106: 61686 | O106: 3.1
A107: H18 | B107: =VLOOKUP(A107,分群碼名稱!A:B,2) -> 百貨 | C107: 彈簧.彈片 | D107: 1400 | E107: 0 | F107: 1400 | G107: 2645 | H107: 0 | I107: 0 | J107: 2645 | K107: 1.89 | L107: 1760 | M107: 1.26 | N107: 2100 | O107: 1.5
A108: H22 | B108: =VLOOKUP(A108,分群碼名稱!A:B,2) -> 百貨 | C108: 泡綿 | D108: 0 | E108: 0 | F108: 0 | G108: 0 | H108: 0 | I108: 0 | J108: 0 | K108: 0 | L108: -5621 | M108: 0 | N108: 0 | O108: 0
A109: H23 | B109: =VLOOKUP(A109,分群碼名稱!A:B,2) -> 百貨 | C109: 氣泡袋(紙) | D109: 0 | E109: 0 | F109: 0 | G109: 0 | H109: 0 | I109: 0 | J109: 0 | K109: 0 | L109: -33730 | M109: 0 | N109: 0 | O109: 0
A110: H24 | B110: =VLOOKUP(A110,分群碼名稱!A:B,2) -> 百貨 | C110: 保麗隆 | D110: 0 | E110: 0 | F110: 0 | G110: 0 | H110: 0 | I110: 0 | J110: 0 | K110: 0 | L110: -2909 | M110: 0 | N110: 0 | O110: 0
A111: H25 | B111: =VLOOKUP(A111,分群碼名稱!A:B,2) -> 百貨 | C111: 通風板 | D111: 0 | E111: 0 | F111: 0 | G111: 0 | H111: 0 | I111: 0 | J111: 0 | K111: 0 | L111: -404 | M111: 0 | N111: 0 | O111: 0
A112: H28 | B112: =VLOOKUP(A112,分群碼名稱!A:B,2) -> 百貨 | C112: 結合扣 | D112: 0 | E112: 0 | F112: 0 | G112: 0 | H112: 0 | I112: 0 | J112: 0 | K112: 0 | L112: -52 | M112: 0 | N112: 0 | O112: 0
A113: H30 | B113: =VLOOKUP(A113,分群碼名稱!A:B,2) -> 百貨 | C113: 護蓋.防塵蓋 | D113: 1000 | E113: 0 | F113: 1000 | G113: 2802 | H113: 0 | I113: 0 | J113: 2802 | K113: 2.8 | L113: 2509 | M113: 2.51 | N113: 2509 | O113: 2.51
A114: H32 | B114: =VLOOKUP(A114,分群碼名稱!A:B,2) -> 百貨 | C114: 固定塑膠類 | D114: 59317 | E114: 0 | F114: 59317 | G114: 65693 | H114: 0 | I114: 0 | J114: 65693 | K114: 1.11 | L114: 61073 | M114: 1.03 | N114: 61176 | O114: 1.03
A115: H35 | B115: =VLOOKUP(A115,分群碼名稱!A:B,2) -> 百貨 | C115: 端子 | D115: 14000 | E115: 0 | F115: 14000 | G115: 51014 | H115: 0 | I115: 0 | J115: 51014 | K115: 3.64 | L115: 39817 | M115: 2.84 | N115: 39380 | O115: 2.81
...

Sheet 樞紐
A3: 列標籤 | B3: 加總 - 銷售數量 | C3: 加總 - 銷退數量 | D3: 加總 - 數量合計 | E3: 加總 - 銷貨收入 | F3: 加總 - 銷貨折讓 | G3: 加總 - 銷貨退回 | H3: 加總 - 銷貨淨額 | I3: 加總 - 銷貨成本(實際)
A4: 大燈 | B4: 1317573 | C4: -2018 | D4: 1315555 | E4: 2170330647 | F4: -1049306 | G4: -9259497 | H4: 2160021844 | I4: 1441846094
A5: 百貨 | B5: 364473 | C5: -139 | D5: 364334 | E5: 46430753 | F5: -16354672 | G5: -6707 | H5: 30069374 | I5: 29892368
A6: 角燈 | B6: 401564 | C6: -27 | D6: 401537 | E6: 64613390 | F6: -837 | G6: -6883 | H6: 64605670 | I6: 38844060
A7: 其他燈 | B7: 3186 | C7: 0 | D7: 3186 | E7: 1689230 | F7: 0 | G7: 0 | H7: 1689230 | I7: 1596512
A8: 前燈 | B8: 207671 | C8: -24 | D8: 207647 | E8: 65255358 | F8: -2557 | G8: -31692 | H8: 65221109 | I8: 36469643
A9: 後燈 | B9: 1114072 | C9: -291 | D9: 1113781 | E9: 767200242 | F9: -109732 | G9: -281153 | H9: 766809357 | I9: 459687789
A10: 倒車燈 | B10: 79581 | C10: -43 | D10: 79538 | E10: 53398315 | F10: -1599 | G10: -48231 | H10: 53348485 | I10: 32447787
A11: 原物料 | B11: 167485 | C11: -11 | D11: 167474 | E11: 4586590 | F11: 0 | G11: -1600 | H11: 4584990 | I11: 4155309
A12: 牌照燈 | B12: 90206 | C12: 0 | D12: 90206 | E12: 5669271 | F12: 0 | G12: 0 | H12: 5669271 | I12: 4894848
A13: 燈座 | B13: 144736 | C13: -3 | D13: 144733 | E13: 12250934 | F13: -69 | G13: -47 | H13: 12250818 | I13: 14073717
A14: 邊燈 | B14: 243880 | C14: -21 | D14: 243859 | E14: 27332579 | F14: -294 | G14: -3717 | H14: 27328568 | I14: 11889135
A15: 霧燈 | B15: 231595 | C15: -24 | D15: 231571 | E15: 133831538 | F15: -3289 | G15: -34902 | H15: 133793347 | I15: 77860378
... A17: 總計 | B17: 4366022 | C17: -2601 | D17: 4363421 | E17: 3356908649 | F17: -17522355 | G17: -9421997 | H17: 3329964297 | I17: 2153657640

Sheet 分群碼名稱
A1: 分群碼 | B1: 大類
A2: A00 | B2: 燈座
A3: A03 | B3: 百貨
A4: A04 | B4: 百貨
A5: A06 | B5: 百貨
A6: A08 | B6: 百貨
A7: A09 | B7: 百貨
A8: A10 | B8: 百貨
A9: A11 | B9: 大燈
A10: A12 | B10: 燈座
A11: A13 | B11: 倒車燈
A12: A14 | B12: 邊燈
... A73: P90 | B73: 百貨
